Error processing line 1 of /home/zhaos5/anaconda3/lib/python3.6/site-packages/protobuf-3.6.0-py3.6-nspkg.pth:

  Traceback (most recent call last):
    File "/home/zhaos5/anaconda3/lib/python3.6/site.py", line 168, in addpackage
      exec(line)
    File "<string>", line 1, in <module>
    File "<frozen importlib._bootstrap>", line 568, in module_from_spec
  AttributeError: 'NoneType' object has no attribute 'loader'

Remainder of file ignored
/home/zhaos5/anaconda3/lib/python3.6/site-packages/psycopg2/__init__.py:144: UserWarning: The psycopg2 wheel package will be renamed from release 2.8; in order to keep installing from binary please use "pip install psycopg2-binary" instead. For details see: <http://initd.org/psycopg/docs/install.html#binary-install-from-pypi>.
  """)
 * Running on http://0.0.0.0:5000/ (Press CTRL+C to quit)
[2019-07-30 14:52:23,617] ERROR in app: Exception on /wsd [POST]
Traceback (most recent call last):
  File "/home/zhaos5/anaconda3/lib/python3.6/site-packages/flask/app.py", line 1982, in wsgi_app
    response = self.full_dispatch_request()
  File "/home/zhaos5/anaconda3/lib/python3.6/site-packages/flask/app.py", line 1614, in full_dispatch_request
    rv = self.handle_user_exception(e)
  File "/home/zhaos5/anaconda3/lib/python3.6/site-packages/flask_cors/extension.py", line 161, in wrapped_function
    return cors_after_request(app.make_response(f(*args, **kwargs)))
  File "/home/zhaos5/anaconda3/lib/python3.6/site-packages/flask/app.py", line 1517, in handle_user_exception
    reraise(exc_type, exc_value, tb)
  File "/home/zhaos5/anaconda3/lib/python3.6/site-packages/flask/_compat.py", line 33, in reraise
    raise value
  File "/home/zhaos5/anaconda3/lib/python3.6/site-packages/flask/app.py", line 1612, in full_dispatch_request
    rv = self.dispatch_request()
  File "/home/zhaos5/anaconda3/lib/python3.6/site-packages/flask/app.py", line 1598, in dispatch_request
    return self.view_functions[rule.endpoint](**req.view_args)
  File "/home/luoz3/wsd_clone/pipeline/server_clone.py", line 357, in wsd_single_text
    txt = re.sub(r"\*\*DATE\b(\[.*?\])?", "DATE-DEID", txt)
UnboundLocalError: local variable 'txt' referenced before assignment
172.31.0.164 - - [30/Jul/2019 14:52:23] "[1m[35mPOST /wsd HTTP/1.1[0m" 500 -
[2019-07-30 14:52:25,148] ERROR in app: Exception on /wsd [POST]
Traceback (most recent call last):
  File "/home/zhaos5/anaconda3/lib/python3.6/site-packages/flask/app.py", line 1982, in wsgi_app
    response = self.full_dispatch_request()
  File "/home/zhaos5/anaconda3/lib/python3.6/site-packages/flask/app.py", line 1614, in full_dispatch_request
    rv = self.handle_user_exception(e)
  File "/home/zhaos5/anaconda3/lib/python3.6/site-packages/flask_cors/extension.py", line 161, in wrapped_function
    return cors_after_request(app.make_response(f(*args, **kwargs)))
  File "/home/zhaos5/anaconda3/lib/python3.6/site-packages/flask/app.py", line 1517, in handle_user_exception
    reraise(exc_type, exc_value, tb)
  File "/home/zhaos5/anaconda3/lib/python3.6/site-packages/flask/_compat.py", line 33, in reraise
    raise value
  File "/home/zhaos5/anaconda3/lib/python3.6/site-packages/flask/app.py", line 1612, in full_dispatch_request
    rv = self.dispatch_request()
  File "/home/zhaos5/anaconda3/lib/python3.6/site-packages/flask/app.py", line 1598, in dispatch_request
    return self.view_functions[rule.endpoint](**req.view_args)
  File "/home/luoz3/wsd_clone/pipeline/server_clone.py", line 357, in wsd_single_text
    txt = re.sub(r"\*\*DATE\b(\[.*?\])?", "DATE-DEID", txt)
UnboundLocalError: local variable 'txt' referenced before assignment
172.31.0.164 - - [30/Jul/2019 14:52:25] "[1m[35mPOST /wsd HTTP/1.1[0m" 500 -
Error processing line 1 of /home/zhaos5/anaconda3/lib/python3.6/site-packages/protobuf-3.6.0-py3.6-nspkg.pth:

  Traceback (most recent call last):
    File "/home/zhaos5/anaconda3/lib/python3.6/site.py", line 168, in addpackage
      exec(line)
    File "<string>", line 1, in <module>
    File "<frozen importlib._bootstrap>", line 568, in module_from_spec
  AttributeError: 'NoneType' object has no attribute 'loader'

Remainder of file ignored
/home/zhaos5/anaconda3/lib/python3.6/site-packages/psycopg2/__init__.py:144: UserWarning: The psycopg2 wheel package will be renamed from release 2.8; in order to keep installing from binary please use "pip install psycopg2-binary" instead. For details see: <http://initd.org/psycopg/docs/install.html#binary-install-from-pypi>.
  """)
 * Running on http://0.0.0.0:5000/ (Press CTRL+C to quit)
172.31.0.164 - - [30/Jul/2019 15:11:56] "[37mPOST /wsd HTTP/1.1[0m" 200 -
Error processing line 1 of /home/zhaos5/anaconda3/lib/python3.6/site-packages/protobuf-3.6.0-py3.6-nspkg.pth:

  Traceback (most recent call last):
    File "/home/zhaos5/anaconda3/lib/python3.6/site.py", line 168, in addpackage
      exec(line)
    File "<string>", line 1, in <module>
    File "<frozen importlib._bootstrap>", line 568, in module_from_spec
  AttributeError: 'NoneType' object has no attribute 'loader'

Remainder of file ignored
/home/zhaos5/anaconda3/lib/python3.6/site-packages/psycopg2/__init__.py:144: UserWarning: The psycopg2 wheel package will be renamed from release 2.8; in order to keep installing from binary please use "pip install psycopg2-binary" instead. For details see: <http://initd.org/psycopg/docs/install.html#binary-install-from-pypi>.
  """)
 * Running on http://0.0.0.0:5000/ (Press CTRL+C to quit)
172.31.0.164 - - [30/Jul/2019 15:24:18] "[37mPOST /wsd HTTP/1.1[0m" 200 -
Error: Could not find or load main class edu.stanford.nlp.pipeline.StanfordCoreNLPServer
